<!--
================================================================
  KISTAR Hand (Ver2) - MuJoCo MJCF
  Converted from kistar_hand.urdf (Made by Jaesung Lee, PRIME Lab)
  Last update: 2026-04-19
================================================================
  Joints     : 16 hinge joints (3 mimic via equality constraint)
  Actuators  : 13 position actuators (master joints only)
  Mimic      : *_joint_3 follows *_joint_2  (index, middle, ring)
               thumb_joint_3 is independent (no mechanical coupling
               via finger_halfmotor link in the URDF)
  Contact    : disabled (for stable kinematic preview)
================================================================
-->
<mujoco model="KISTAR_HAND">
  <compiler angle="radian" meshdir="meshes/kistar/" boundmass="0.0001" boundinertia="1e-09"/>

  <option timestep="0.0005" integrator="implicitfast" solver="Newton" iterations="100" tolerance="1e-10">
    <flag contact="disable"/>
  </option>

  <default>
    <position kp="30" kv="0.7" forcerange="-100 100"/>
    <geom contype="0" conaffinity="0" group="1" density="0" rgba="0.2 0.2 0.2 1"/>
  </default>

  <asset>
    <mesh name="mount"            file="mount.STL"/>
    <mesh name="palm"             file="Palm.STL"/>
    <mesh name="thp1"             file="thp1.STL"/>
    <mesh name="thumb_link_0"     file="thumb_link_0.STL"/>
    <mesh name="thumb_link_1"     file="thumb_link_1.STL"/>
    <mesh name="thumb_link_2"     file="thumb_link_2.STL"/>
    <mesh name="finger_basemotor" file="finger_basemotor.STL"/>
    <mesh name="finger_link_0"    file="finger_link_0.STL"/>
    <mesh name="finger_link_1"    file="finger_link_1.STL"/>
    <mesh name="finger_link_2"    file="finger_link_2.STL"/>
    <mesh name="finger_halfmotor" file="finger_halfmotor.STL"/>
    <mesh name="Tip_braket"       file="Tip_braket.STL"/>
    <mesh name="finger_tip"       file="finger_tip.STL"/>
    <mesh name="sensor"           file="sensor.STL"/>
  </asset>

  <worldbody>

    <body name="mount" pos="0 0 0">
      <geom type="mesh" mesh="mount"/>

      <body name="palm" pos="0 0 0.071">
        <inertial pos="-0.01669 0.00079 -0.02862" mass="0.15476"
                  fullinertia="0.00032705182 0.00035100257 0.00016323150 -0.00001050022 0.00005386046 -0.00000337009"/>
        <geom type="mesh" mesh="palm" rgba="0 0 0 1"/>

        <!-- ============================== THUMB ============================== -->
        <body name="thumb_basemotor" pos="-0.02325 0.01224 -0.02988" euler="-0.0873 0 0">
          <geom type="mesh" mesh="thp1"/>

          <body name="thumb_link_0" pos="0.0197 0.002 0" euler="-1.5708 0 0">
            <inertial pos="-0.00714 0 0.02081" mass="0.02423"
                      fullinertia="0.00001317338 0.00001497641 0.00000318767 0 -0.00000386319 0"/>
            <joint name="thumb_joint_0" axis="0 1 0" range="0 1.5708"
                   damping="0.0414019" frictionloss="0.0523963"/>
            <geom type="mesh" mesh="thumb_link_0"/>

            <body name="thumb_link_1" pos="-0.002 0 0.036">
              <inertial pos="0.00043 0 0.00345" mass="0.00191"
                        fullinertia="0.00000023689 0.00000007651 0.00000021019 0 0.00000000784 0"/>
              <joint name="thumb_joint_1" axis="0 0 1" range="-1.5708 1.5708"
                     damping="0.00587541" frictionloss="0.0150275"/>
              <geom type="mesh" mesh="thumb_link_1"/>

              <body name="thumb_link_2" pos="0.002 0 0.0102">
                <inertial pos="-0.00154 0.00021 0.01842" mass="0.01827"
                          fullinertia="0.00000796138 0.00000752132 0.00000105696 -0.00000001114 -0.00000053085 0.00000001719"/>
                <joint name="thumb_joint_2" axis="0 1 0" range="0 1.5708"
                       damping="0.010638" frictionloss="0.00616359"/>
                <geom type="mesh" mesh="thumb_link_2"/>

                <body name="thumb_sensor_0" pos="0.00525 0 0.00865">
                  <geom type="mesh" mesh="sensor"/>
                </body>
                <body name="thumb_sensor_1" pos="0.00525 0 0.02485">
                  <geom type="mesh" mesh="sensor"/>
                </body>

                <body name="thumb_tip_braket" pos="0 0 0.0335">
                  <inertial pos="-0.00190 0 0.01626" mass="0.00719"
                            fullinertia="0.00073654 0.00020117 0.00071277 0 -0.00002227 0"/>
                  <joint name="thumb_joint_3" axis="0 1 0" range="0 1.5708"
                         damping="0.0226948" frictionloss="0.0227036"/>
                  <geom type="mesh" mesh="Tip_braket"/>

                  <body name="thumb_tip" pos="-0.002 0 0.010">
                    <inertial pos="0 0 0.00816" mass="0.00719"
                              fullinertia="0.00030378 0.00030378 0.00027029 0 0 0"/>
                    <geom type="mesh" mesh="finger_tip"/>
                  </body>
                </body>
              </body>
            </body>
          </body>
        </body>

        <!-- ============================== INDEX ============================== -->
        <body name="index_basemotor" pos="-0.02325 0.02935 -0.0004" euler="-0.0873 0 0">
          <geom type="mesh" mesh="finger_basemotor"/>

          <body name="index_link_0" pos="0.02325 0 0.0047">
            <inertial pos="-0.00353 0 0.00948" mass="0.00473"
                      fullinertia="0.00000076951 0.00000092515 0.00000062017 0 -0.00000009858 0"/>
            <joint name="index_joint_0" axis="1 0 0" range="-0.261799 0.261799"
                   damping="0.0414019" frictionloss="0.0523963"/>
            <geom type="mesh" mesh="finger_link_0"/>

            <body name="index_link_1" pos="0.002 0 0.0195">
              <inertial pos="-0.00166 0 0.01675" mass="0.03549"
                        fullinertia="0.00001607025 0.00001510746 0.00000219008 0 -0.00000098913 0"/>
              <joint name="index_joint_1" axis="0 1 0" range="0 1.5708"
                     damping="0.00587541" frictionloss="0.0150275"/>
              <geom type="mesh" mesh="finger_link_1"/>

              <body name="index_sensor_0" pos="0.00525 0 0.00865">
                <geom type="mesh" mesh="sensor"/>
              </body>
              <body name="index_sensor_1" pos="0.00525 0 0.02485">
                <geom type="mesh" mesh="sensor"/>
              </body>

              <body name="index_link_2" pos="0 0 0.0335">
                <inertial pos="-0.00146 0 0.00659" mass="0.00300"
                          fullinertia="0.00200547 0.00050465 0.00196277 0 -0.00005438 0"/>
                <joint name="index_joint_2" axis="0 1 0" range="0 1.5708"
                       damping="0.010638" frictionloss="0.00616359"/>
                <geom type="mesh" mesh="finger_link_2"/>

                <body name="index_finger_motor" pos="0 0 0.0267">
                  <inertial pos="-0.00163 0 0.00677" mass="0.015"
                            fullinertia="0.00041537 0.00028785 0.00029216 0 0.00000109 0"/>
                  <geom type="mesh" mesh="finger_halfmotor"/>

                  <body name="index_sensor_2" pos="0.00525 0 -0.00865">
                    <geom type="mesh" mesh="sensor"/>
                  </body>

                  <body name="index_tip_braket" pos="0 0 0">
                    <inertial pos="-0.00137 0 0.00621" mass="0.00719"
                              fullinertia="0.00073654 0.00020117 0.00071277 0 -0.00002227 0"/>
                    <joint name="index_joint_3" axis="0 1 0" range="0 1.5708"
                           damping="0.0226948" frictionloss="0.0227036"/>
                    <geom type="mesh" mesh="Tip_braket"/>

                    <body name="index_tip" pos="-0.002 0 0.010">
                      <inertial pos="0 0 0.00816" mass="0.00719"
                                fullinertia="0.00030378 0.00030378 0.00027029 0 0 0"/>
                      <geom type="mesh" mesh="finger_tip"/>
                    </body>
                  </body>
                </body>
              </body>
            </body>
          </body>
        </body>

        <!-- ============================== MIDDLE ============================== -->
        <body name="middle_basemotor" pos="-0.02325 0 0">
          <geom type="mesh" mesh="finger_basemotor"/>

          <body name="middle_link_0" pos="0.02325 0 0.0047">
            <inertial pos="-0.00353 0 0.00948" mass="0.00473"
                      fullinertia="0.00000076951 0.00000092515 0.00000062017 0 -0.00000009858 0"/>
            <joint name="middle_joint_0" axis="1 0 0" range="-0.261799 0.261799"
                   damping="0.0414019" frictionloss="0.0523963"/>
            <geom type="mesh" mesh="finger_link_0"/>

            <body name="middle_link_1" pos="0.002 0 0.0195">
              <inertial pos="-0.00166 0 0.01675" mass="0.03549"
                        fullinertia="0.00001607025 0.00001510746 0.00000219008 0 -0.00000098913 0"/>
              <joint name="middle_joint_1" axis="0 1 0" range="0 1.5708"
                     damping="0.00587541" frictionloss="0.0150275"/>
              <geom type="mesh" mesh="finger_link_1"/>

              <body name="middle_sensor_0" pos="0.00525 0 0.00865">
                <geom type="mesh" mesh="sensor"/>
              </body>
              <body name="middle_sensor_1" pos="0.00525 0 0.02485">
                <geom type="mesh" mesh="sensor"/>
              </body>

              <body name="middle_link_2" pos="0 0 0.0335">
                <inertial pos="-0.00146 0 0.00659" mass="0.00300"
                          fullinertia="0.00200547 0.00050465 0.00196277 0 -0.00005438 0"/>
                <joint name="middle_joint_2" axis="0 1 0" range="0 1.5708"
                       damping="0.010638" frictionloss="0.00616359"/>
                <geom type="mesh" mesh="finger_link_2"/>

                <body name="middle_finger_motor" pos="0 0 0.0267">
                  <inertial pos="-0.00163 0 0.00677" mass="0.015"
                            fullinertia="0.00041537 0.00028785 0.00029216 0 0.00000109 0"/>
                  <geom type="mesh" mesh="finger_halfmotor"/>

                  <body name="middle_sensor_2" pos="0.00525 0 -0.00865">
                    <geom type="mesh" mesh="sensor"/>
                  </body>

                  <body name="middle_tip_braket" pos="0 0 0">
                    <inertial pos="-0.00137 0 0.00621" mass="0.00719"
                              fullinertia="0.00073654 0.00020117 0.00071277 0 -0.00002227 0"/>
                    <joint name="middle_joint_3" axis="0 1 0" range="0 1.5708"
                           damping="0.0226948" frictionloss="0.0227036"/>
                    <geom type="mesh" mesh="Tip_braket"/>

                    <body name="middle_tip" pos="-0.002 0 0.010">
                      <inertial pos="0 0 0.00816" mass="0.00719"
                                fullinertia="0.00030378 0.00030378 0.00027029 0 0 0"/>
                      <geom type="mesh" mesh="finger_tip"/>
                    </body>
                  </body>
                </body>
              </body>
            </body>
          </body>
        </body>

        <!-- ============================== RING ============================== -->
        <body name="ring_basemotor" pos="-0.02325 -0.02935 -0.0004" euler="0.0873 0 0">
          <geom type="mesh" mesh="finger_basemotor"/>

          <body name="ring_link_0" pos="0.02325 0 0.0047">
            <inertial pos="-0.00353 0 0.00948" mass="0.00473"
                      fullinertia="0.00000076951 0.00000092515 0.00000062017 0 -0.00000009858 0"/>
            <joint name="ring_joint_0" axis="1 0 0" range="-0.261799 0.261799"
                   damping="0.0414019" frictionloss="0.0523963"/>
            <geom type="mesh" mesh="finger_link_0"/>

            <body name="ring_link_1" pos="0.002 0 0.0195">
              <inertial pos="-0.00166 0 0.01675" mass="0.03549"
                        fullinertia="0.00001607025 0.00001510746 0.00000219008 0 -0.00000098913 0"/>
              <joint name="ring_joint_1" axis="0 1 0" range="0 1.5708"
                     damping="0.00587541" frictionloss="0.0150275"/>
              <geom type="mesh" mesh="finger_link_1"/>

              <body name="ring_sensor_0" pos="0.00525 0 0.00865">
                <geom type="mesh" mesh="sensor"/>
              </body>
              <body name="ring_sensor_1" pos="0.00525 0 0.02485">
                <geom type="mesh" mesh="sensor"/>
              </body>

              <body name="ring_link_2" pos="0 0 0.0335">
                <inertial pos="-0.00146 0 0.00659" mass="0.00300"
                          fullinertia="0.00200547 0.00050465 0.00196277 0 -0.00005438 0"/>
                <joint name="ring_joint_2" axis="0 1 0" range="0 1.5708"
                       damping="0.010638" frictionloss="0.00616359"/>
                <geom type="mesh" mesh="finger_link_2"/>

                <body name="ring_finger_motor" pos="0 0 0.0267">
                  <inertial pos="-0.00163 0 0.00677" mass="0.015"
                            fullinertia="0.00041537 0.00028785 0.00029216 0 0.00000109 0"/>
                  <geom type="mesh" mesh="finger_halfmotor"/>

                  <body name="ring_sensor_2" pos="0.00525 0 -0.00865">
                    <geom type="mesh" mesh="sensor"/>
                  </body>

                  <body name="ring_tip_braket" pos="0 0 0">
                    <inertial pos="-0.00137 0 0.00621" mass="0.00719"
                              fullinertia="0.00073654 0.00020117 0.00071277 0 -0.00002227 0"/>
                    <joint name="ring_joint_3" axis="0 1 0" range="0 1.5708"
                           damping="0.0226948" frictionloss="0.0227036"/>
                    <geom type="mesh" mesh="Tip_braket"/>

                    <body name="ring_tip" pos="-0.002 0 0.010">
                      <inertial pos="0 0 0.00816" mass="0.00719"
                                fullinertia="0.00030378 0.00030378 0.00027029 0 0 0"/>
                      <geom type="mesh" mesh="finger_tip"/>
                    </body>
                  </body>
                </body>
              </body>
            </body>
          </body>
        </body>

      </body>
    </body>

  </worldbody>

  <actuator>
    <position name="thumb_act_0"  joint="thumb_joint_0"  ctrlrange="0 1.5708"/>
    <position name="thumb_act_1"  joint="thumb_joint_1"  ctrlrange="-1.5708 1.5708"/>
    <position name="thumb_act_2"  joint="thumb_joint_2"  ctrlrange="0 1.5708"/>
    <position name="thumb_act_3"  joint="thumb_joint_3"  ctrlrange="0 1.5708"/>

    <position name="index_act_0"  joint="index_joint_0"  ctrlrange="-0.261799 0.261799"/>
    <position name="index_act_1"  joint="index_joint_1"  ctrlrange="0 1.5708"/>
    <position name="index_act_2"  joint="index_joint_2"  ctrlrange="0 1.5708"/>

    <position name="middle_act_0" joint="middle_joint_0" ctrlrange="-0.261799 0.261799"/>
    <position name="middle_act_1" joint="middle_joint_1" ctrlrange="0 1.5708"/>
    <position name="middle_act_2" joint="middle_joint_2" ctrlrange="0 1.5708"/>

    <position name="ring_act_0"   joint="ring_joint_0"   ctrlrange="-0.261799 0.261799"/>
    <position name="ring_act_1"   joint="ring_joint_1"   ctrlrange="0 1.5708"/>
    <position name="ring_act_2"   joint="ring_joint_2"   ctrlrange="0 1.5708"/>
  </actuator>

  <!-- Kinematic 1:1 coupling (rigid 4-bar linkage via finger_halfmotor link). -->
  <!-- solref="0.0005 1": 0.5ms time const - near-instant tracking            -->
  <!-- solimp="0.999 0.9999 1e-5": stiff constraint - virtually no slack       -->
  <equality>
    <joint joint1="index_joint_3"  joint2="index_joint_2"  polycoef="0 1 0 0 0" solref="0.0005 1" solimp="0.999 0.9999 1e-5"/>
    <joint joint1="middle_joint_3" joint2="middle_joint_2" polycoef="0 1 0 0 0" solref="0.0005 1" solimp="0.999 0.9999 1e-5"/>
    <joint joint1="ring_joint_3"   joint2="ring_joint_2"   polycoef="0 1 0 0 0" solref="0.0005 1" solimp="0.999 0.9999 1e-5"/>
  </equality>
</mujoco>
