<mujoco model="KISTAR_SON_RIGHT">
  <compiler angle="radian" meshdir="01_kistar_son_STL/" boundmass="0.0001" boundinertia="1e-09"/>

  <option timestep="0.0005" integrator="implicitfast" solver="Newton" iterations="100" tolerance="1e-10">
    <flag contact="disable"/>
  </option>

  <asset>
    <mesh name="right_hand_base_link" content_type="model/stl" file="right_hand_base_link.STL"/>
    <mesh name="right_hand_base_front_link" content_type="model/stl" file="right_hand_base_front_link.STL"/>
    <mesh name="right_hand_base_back_link" content_type="model/stl" file="right_hand_base_back_link.STL"/>
    <mesh name="right_hand_thumb_base_link" content_type="model/stl" file="right_hand_thumb_base_link.STL"/>
    <mesh name="right_hand_thumb_0_link" content_type="model/stl" file="right_hand_thumb_0_link.STL"/>
    <mesh name="right_hand_thumb_1_link" content_type="model/stl" file="right_hand_thumb_1_link.STL"/>
    <mesh name="right_hand_thumb_2_link" content_type="model/stl" file="right_hand_thumb_2_link.STL"/>
    <mesh name="right_hand_thumb_2_upper_link" content_type="model/stl" file="right_hand_thumb_2_upper_link.STL"/>
    <mesh name="right_hand_thumb_2_front_link" content_type="model/stl" file="right_hand_thumb_2_front_link.STL"/>
    <mesh name="right_hand_thumb_2_back_link" content_type="model/stl" file="right_hand_thumb_2_back_link.STL"/>
    <mesh name="right_hand_thumb_3_link" content_type="model/stl" file="right_hand_thumb_3_link.STL"/>
    <mesh name="right_hand_thumb_3_front_link" content_type="model/stl" file="right_hand_thumb_3_front_link.STL"/>
    <mesh name="right_hand_thumb_3_back_link" content_type="model/stl" file="right_hand_thumb_3_back_link.STL"/>
    <mesh name="right_hand_thumb_4_link" content_type="model/stl" file="right_hand_thumb_4_link.STL"/>
    <mesh name="right_hand_thumb_4_front_link" content_type="model/stl" file="right_hand_thumb_4_front_link.STL"/>
    <mesh name="right_hand_thumb_4_back_link" content_type="model/stl" file="right_hand_thumb_4_back_link.STL"/>
    <mesh name="right_hand_finger_0_link" content_type="model/stl" file="right_hand_finger_0_link.STL"/>
    <mesh name="right_hand_finger_0_upper_link" content_type="model/stl" file="right_hand_finger_0_upper_link.STL"/>
    <mesh name="right_hand_finger_1_link" content_type="model/stl" file="right_hand_finger_1_link.STL"/>
    <mesh name="right_hand_finger_1_upper_link" content_type="model/stl" file="right_hand_finger_1_upper_link.STL"/>
    <mesh name="right_hand_finger_1_front_link" content_type="model/stl" file="right_hand_finger_1_front_link.STL"/>
    <mesh name="right_hand_finger_1_back_link" content_type="model/stl" file="right_hand_finger_1_back_link.STL"/>
    <mesh name="right_hand_finger_2_link" content_type="model/stl" file="right_hand_finger_2_link.STL"/>
    <mesh name="right_hand_finger_2_front_link" content_type="model/stl" file="right_hand_finger_2_front_link.STL"/>
    <mesh name="right_hand_finger_2_back_link" content_type="model/stl" file="right_hand_finger_2_back_link.STL"/>
    <mesh name="right_hand_finger_3_link" content_type="model/stl" file="right_hand_finger_3_link.STL"/>
    <mesh name="right_hand_finger_3_front_link" content_type="model/stl" file="right_hand_finger_3_front_link.STL"/>
    <mesh name="right_hand_finger_3_back_link" content_type="model/stl" file="right_hand_finger_3_back_link.STL"/>
    <mesh name="right_hand_little_0_link" content_type="model/stl" file="right_hand_little_0_link.STL"/>
    <mesh name="right_hand_little_0_upper_link" content_type="model/stl" file="right_hand_little_0_upper_link.STL"/>
    <mesh name="right_hand_little_0_front_link" content_type="model/stl" file="right_hand_little_0_front_link.STL"/>
    <mesh name="right_hand_little_0_back_link" content_type="model/stl" file="right_hand_little_0_back_link.STL"/>
    <mesh name="right_hand_little_1_link" content_type="model/stl" file="right_hand_little_1_link.STL"/>
    <mesh name="right_hand_little_1_front_link" content_type="model/stl" file="right_hand_little_1_front_link.STL"/>
    <mesh name="right_hand_little_1_back_link" content_type="model/stl" file="right_hand_little_1_back_link.STL"/>
  </asset>

  <worldbody>
    <geom type="mesh" mesh="right_hand_base_link"/>
    <geom type="mesh" contype="0" conaffinity="0" group="1" density="0" rgba="0.2 0.2 0.2 1" mesh="right_hand_base_link"/>
    <geom type="mesh" mesh="right_hand_base_front_link"/>
    <geom type="mesh" contype="0" conaffinity="0" group="1" density="0" rgba="0.2 0.2 0.2 1" mesh="right_hand_base_front_link"/>
    <geom type="mesh" mesh="right_hand_base_back_link"/>
    <geom type="mesh" contype="0" conaffinity="0" group="1" density="0" rgba="0.2 0.2 0.2 1" mesh="right_hand_base_back_link"/>
    <geom pos="0.03062 0.0213 0.0253" quat="0.923879 0 0 -0.382684" type="mesh" mesh="right_hand_thumb_base_link"/>
    <geom pos="0.03062 0.0213 0.0253" quat="0.923879 0 0 -0.382684" type="mesh" contype="0" conaffinity="0" group="1" density="0" rgba="0.2 0.2 0.2 1" mesh="right_hand_thumb_base_link"/>
    <body name="right_hand_thumb_0_link" pos="0.03062 0.0213 0.0253" quat="0.923879 0 0 -0.382684">
      <inertial pos="0 0 0" mass="0.0001" diaginertia="1e-09 1e-09 1e-09"/>
      <joint name="right_hand_thumb_0_joint" pos="0 0 0" axis="0 0 -1" range="-0.7854 0.7854" actuatorfrcrange="-0.2 0.2" damping="0.1" frictionloss="0.03"/>
      <geom type="mesh" mesh="right_hand_thumb_0_link"/>
      <geom type="mesh" contype="0" conaffinity="0" group="1" density="0" rgba="0.2 0.2 0.2 1" mesh="right_hand_thumb_0_link"/>
      <body name="right_hand_thumb_1_link">
        <inertial pos="0 0 0" mass="0.0001" diaginertia="1e-09 1e-09 1e-09"/>
        <joint name="right_hand_thumb_1_joint" pos="0 0 0" axis="1 0 0" range="-0.7854 0.7854" actuatorfrcrange="-0.2 0.2" damping="0.1" frictionloss="0.03"/>
        <geom type="mesh" mesh="right_hand_thumb_1_link"/>
        <geom type="mesh" contype="0" conaffinity="0" group="1" density="0" rgba="0.2 0.2 0.2 1" mesh="right_hand_thumb_1_link"/>
        <body name="right_hand_thumb_2_link" pos="0 0.01303 0.01303" quat="0.923879 0.382684 0 0">
          <inertial pos="0.000139112 0.0204495 -0.00637928" quat="0.641996 0.766591 0.0107085 -0.00808202" mass="0.0473" diaginertia="3.50741e-05 3.31524e-05 4.59604e-06"/>
          <joint name="right_hand_thumb_2_joint" pos="0 0 0" axis="0 1 0" range="-1.0472 1.0472" actuatorfrcrange="-0.2 0.2" damping="0.1" frictionloss="0.03"/>
          <geom type="mesh" mesh="right_hand_thumb_2_link"/>
          <geom type="mesh" contype="0" conaffinity="0" group="1" density="0" rgba="0.2 0.2 0.2 1" mesh="right_hand_thumb_2_link"/>
          <geom type="mesh" mesh="right_hand_thumb_2_upper_link"/>
          <geom type="mesh" contype="0" conaffinity="0" group="1" density="0" rgba="0.2 0.2 0.2 1" mesh="right_hand_thumb_2_upper_link"/>
          <geom type="mesh" mesh="right_hand_thumb_2_front_link"/>
          <geom type="mesh" contype="0" conaffinity="0" group="1" density="0" rgba="0.2 0.2 0.2 1" mesh="right_hand_thumb_2_front_link"/>
          <geom type="mesh" mesh="right_hand_thumb_2_back_link"/>
          <geom type="mesh" contype="0" conaffinity="0" group="1" density="0" rgba="0.2 0.2 0.2 1" mesh="right_hand_thumb_2_back_link"/>
          <body name="right_hand_thumb_3_link" pos="0 0.0525 -0.00803">
            <inertial pos="0 0.00965884 0.00264116" quat="0.559862 0.43192 -0.43192 0.559862" mass="0.0043" diaginertia="8.76715e-07 7.93572e-07 1.50117e-07"/>
            <joint name="right_hand_thumb_3_joint" pos="0 0 0" axis="1 0 0" range="0 1.5708" actuatorfrcrange="-0.2 0.2" damping="0.1" frictionloss="0.03"/>
            <geom type="mesh" mesh="right_hand_thumb_3_link"/>
            <geom type="mesh" contype="0" conaffinity="0" group="1" density="0" rgba="0.2 0.2 0.2 1" mesh="right_hand_thumb_3_link"/>
            <geom type="mesh" mesh="right_hand_thumb_3_front_link"/>
            <geom type="mesh" contype="0" conaffinity="0" group="1" density="0" rgba="0.2 0.2 0.2 1" mesh="right_hand_thumb_3_front_link"/>
            <geom type="mesh" mesh="right_hand_thumb_3_back_link"/>
            <geom type="mesh" contype="0" conaffinity="0" group="1" density="0" rgba="0.2 0.2 0.2 1" mesh="right_hand_thumb_3_back_link"/>
            <body name="right_hand_thumb_4_link" pos="0 0.026035 0.006217">
              <inertial pos="0 0.00990405 0.00237432" quat="0.453357 0.545572 -0.542025 0.450586" mass="0.0037" diaginertia="6.03488e-07 5.8879e-07 7.76036e-08"/>
              <joint name="right_hand_thumb_4_joint" pos="0 0 0" axis="1 0 0" range="0 1.5708" actuatorfrcrange="-0.2 0.2" damping="0.1" frictionloss="0.03"/>
              <geom type="mesh" mesh="right_hand_thumb_4_link"/>
              <geom type="mesh" contype="0" conaffinity="0" group="1" density="0" rgba="0.2 0.2 0.2 1" mesh="right_hand_thumb_4_link"/>
              <geom type="mesh" mesh="right_hand_thumb_4_front_link"/>
              <geom type="mesh" contype="0" conaffinity="0" group="1" density="0" rgba="0.2 0.2 0.2 1" mesh="right_hand_thumb_4_front_link"/>
              <geom type="mesh" mesh="right_hand_thumb_4_back_link"/>
              <geom type="mesh" contype="0" conaffinity="0" group="1" density="0" rgba="0.2 0.2 0.2 1" mesh="right_hand_thumb_4_back_link"/>
            </body>
          </body>
        </body>
      </body>
    </body>
    <body name="right_hand_index_0_link" pos="0.01475 0.031 0.078">
      <inertial pos="-0.0122417 0 -0.0119424" quat="0.671886 -0.214806 -0.213109 0.676026" mass="0.0434" diaginertia="2.53693e-05 2.22687e-05 4.9021e-06"/>
      <joint name="right_hand_index_0_joint" pos="0 0 0" axis="-1 0 0" range="-0.261799 0.261799" actuatorfrcrange="-0.2 0.2" damping="0.1" frictionloss="0.03"/>
      <geom type="mesh" mesh="right_hand_finger_0_link"/>
      <geom type="mesh" contype="0" conaffinity="0" group="1" density="0" rgba="0.2 0.2 0.2 1" mesh="right_hand_finger_0_link"/>
      <geom type="mesh" mesh="right_hand_finger_0_upper_link"/>
      <geom type="mesh" contype="0" conaffinity="0" group="1" density="0" rgba="0.2 0.2 0.2 1" mesh="right_hand_finger_0_upper_link"/>
      <body name="right_hand_index_1_link" pos="-0.005 0 0.0215">
        <inertial pos="-0.00370794 0 0.0164775" quat="0.708493 0.0301359 0.0309677 0.704393" mass="0.035" diaginertia="2.17876e-05 2.09064e-05 1.87297e-06"/>
        <joint name="right_hand_index_1_joint" pos="0 0 0" axis="0 1 0" range="0 1.5708" actuatorfrcrange="-0.2 0.2" damping="0.1" frictionloss="0.03"/>
        <geom type="mesh" mesh="right_hand_finger_1_link"/>
        <geom type="mesh" contype="0" conaffinity="0" group="1" density="0" rgba="0.2 0.2 0.2 1" mesh="right_hand_finger_1_link"/>
        <geom type="mesh" mesh="right_hand_finger_1_upper_link"/>
        <geom type="mesh" contype="0" conaffinity="0" group="1" density="0" rgba="0.2 0.2 0.2 1" mesh="right_hand_finger_1_upper_link"/>
        <geom type="mesh" mesh="right_hand_finger_1_front_link"/>
        <geom type="mesh" contype="0" conaffinity="0" group="1" density="0" rgba="0.2 0.2 0.2 1" mesh="right_hand_finger_1_front_link"/>
        <geom type="mesh" mesh="right_hand_finger_1_back_link"/>
        <geom type="mesh" contype="0" conaffinity="0" group="1" density="0" rgba="0.2 0.2 0.2 1" mesh="right_hand_finger_1_back_link"/>
        <body name="right_hand_index_2_link" pos="-0.007 0 0.0475">
          <inertial pos="-0.0024886 0 0.00840977" quat="0.989776 0 -0.142633 0" mass="0.0043" diaginertia="7.24293e-07 6.35014e-07 1.49941e-07"/>
          <joint name="right_hand_index_2_joint" pos="0 0 0" axis="0 1 0" range="0 1.5708" actuatorfrcrange="-0.2 0.2" damping="0.1" frictionloss="0.03"/>
          <geom type="mesh" mesh="right_hand_finger_2_link"/>
          <geom type="mesh" contype="0" conaffinity="0" group="1" density="0" rgba="0.2 0.2 0.2 1" mesh="right_hand_finger_2_link"/>
          <geom type="mesh" mesh="right_hand_finger_2_front_link"/>
          <geom type="mesh" contype="0" conaffinity="0" group="1" density="0" rgba="0.2 0.2 0.2 1" mesh="right_hand_finger_2_front_link"/>
          <geom type="mesh" mesh="right_hand_finger_2_back_link"/>
          <geom type="mesh" contype="0" conaffinity="0" group="1" density="0" rgba="0.2 0.2 0.2 1" mesh="right_hand_finger_2_back_link"/>
          <body name="right_hand_index_3_link" pos="0.006217 0 0.026035">
            <inertial pos="-0.00237432 0 0.00990405" quat="0.996547 0.000445186 0.0829215 0.00419741" mass="0.0037" diaginertia="6.00078e-07 5.8879e-07 8.10134e-08"/>
            <joint name="right_hand_index_3_joint" pos="0 0 0" axis="0 1 0" range="0 1.5708" actuatorfrcrange="-0.2 0.2" damping="0.1" frictionloss="0.03"/>
            <geom type="mesh" mesh="right_hand_finger_3_link"/>
            <geom type="mesh" contype="0" conaffinity="0" group="1" density="0" rgba="0.2 0.2 0.2 1" mesh="right_hand_finger_3_link"/>
            <geom type="mesh" mesh="right_hand_finger_3_front_link"/>
            <geom type="mesh" contype="0" conaffinity="0" group="1" density="0" rgba="0.2 0.2 0.2 1" mesh="right_hand_finger_3_front_link"/>
            <geom type="mesh" mesh="right_hand_finger_3_back_link"/>
            <geom type="mesh" contype="0" conaffinity="0" group="1" density="0" rgba="0.2 0.2 0.2 1" mesh="right_hand_finger_3_back_link"/>
          </body>
        </body>
      </body>
    </body>
    <body name="right_hand_middle_0_link" pos="0.01475 0.00701 0.087">
      <inertial pos="-0.0122417 0 -0.0119424" quat="0.671886 -0.214806 -0.213109 0.676026" mass="0.0434" diaginertia="2.53693e-05 2.22687e-05 4.9021e-06"/>
      <joint name="right_hand_middle_0_joint" pos="0 0 0" axis="-1 0 0" range="-0.261799 0.261799" actuatorfrcrange="-0.2 0.2" damping="0.1" frictionloss="0.03"/>
      <geom type="mesh" mesh="right_hand_finger_0_link"/>
      <geom type="mesh" contype="0" conaffinity="0" group="1" density="0" rgba="0.2 0.2 0.2 1" mesh="right_hand_finger_0_link"/>
      <geom type="mesh" mesh="right_hand_finger_0_upper_link"/>
      <geom type="mesh" contype="0" conaffinity="0" group="1" density="0" rgba="0.2 0.2 0.2 1" mesh="right_hand_finger_0_upper_link"/>
      <body name="right_hand_middle_1_link" pos="-0.005 0 0.0215">
        <inertial pos="-0.00370794 0 0.0164775" quat="0.708493 0.0301359 0.0309677 0.704393" mass="0.035" diaginertia="2.17876e-05 2.09064e-05 1.87297e-06"/>
        <joint name="right_hand_middle_1_joint" pos="0 0 0" axis="0 1 0" range="0 1.5708" actuatorfrcrange="-0.2 0.2" damping="0.1" frictionloss="0.03"/>
        <geom type="mesh" mesh="right_hand_finger_1_link"/>
        <geom type="mesh" contype="0" conaffinity="0" group="1" density="0" rgba="0.2 0.2 0.2 1" mesh="right_hand_finger_1_link"/>
        <geom type="mesh" mesh="right_hand_finger_1_upper_link"/>
        <geom type="mesh" contype="0" conaffinity="0" group="1" density="0" rgba="0.2 0.2 0.2 1" mesh="right_hand_finger_1_upper_link"/>
        <geom type="mesh" mesh="right_hand_finger_1_front_link"/>
        <geom type="mesh" contype="0" conaffinity="0" group="1" density="0" rgba="0.2 0.2 0.2 1" mesh="right_hand_finger_1_front_link"/>
        <geom type="mesh" mesh="right_hand_finger_1_back_link"/>
        <geom type="mesh" contype="0" conaffinity="0" group="1" density="0" rgba="0.2 0.2 0.2 1" mesh="right_hand_finger_1_back_link"/>
        <body name="right_hand_middle_2_link" pos="-0.007 0 0.0475">
          <inertial pos="-0.0024886 0 0.00840977" quat="0.989776 0 -0.142633 0" mass="0.0043" diaginertia="7.24293e-07 6.35014e-07 1.49941e-07"/>
          <joint name="right_hand_middle_2_joint" pos="0 0 0" axis="0 1 0" range="0 1.5708" actuatorfrcrange="-0.2 0.2" damping="0.1" frictionloss="0.03"/>
          <geom type="mesh" mesh="right_hand_finger_2_link"/>
          <geom type="mesh" contype="0" conaffinity="0" group="1" density="0" rgba="0.2 0.2 0.2 1" mesh="right_hand_finger_2_link"/>
          <geom type="mesh" mesh="right_hand_finger_2_front_link"/>
          <geom type="mesh" contype="0" conaffinity="0" group="1" density="0" rgba="0.2 0.2 0.2 1" mesh="right_hand_finger_2_front_link"/>
          <geom type="mesh" mesh="right_hand_finger_2_back_link"/>
          <geom type="mesh" contype="0" conaffinity="0" group="1" density="0" rgba="0.2 0.2 0.2 1" mesh="right_hand_finger_2_back_link"/>
          <body name="right_hand_middle_3_link" pos="0.006217 0 0.026035">
            <inertial pos="-0.00237432 0 0.00990405" quat="0.996547 0.000445186 0.0829215 0.00419741" mass="0.0037" diaginertia="6.00078e-07 5.8879e-07 8.10134e-08"/>
            <joint name="right_hand_middle_3_joint" pos="0 0 0" axis="0 1 0" range="0 1.5708" actuatorfrcrange="-0.2 0.2" damping="0.1" frictionloss="0.03"/>
            <geom type="mesh" mesh="right_hand_finger_3_link"/>
            <geom type="mesh" contype="0" conaffinity="0" group="1" density="0" rgba="0.2 0.2 0.2 1" mesh="right_hand_finger_3_link"/>
            <geom type="mesh" mesh="right_hand_finger_3_front_link"/>
            <geom type="mesh" contype="0" conaffinity="0" group="1" density="0" rgba="0.2 0.2 0.2 1" mesh="right_hand_finger_3_front_link"/>
            <geom type="mesh" mesh="right_hand_finger_3_back_link"/>
            <geom type="mesh" contype="0" conaffinity="0" group="1" density="0" rgba="0.2 0.2 0.2 1" mesh="right_hand_finger_3_back_link"/>
          </body>
        </body>
      </body>
    </body>
    <body name="right_hand_ring_0_link" pos="0.01475 -0.017 0.078">
      <inertial pos="-0.0122417 0 -0.0119424" quat="0.671886 -0.214806 -0.213109 0.676026" mass="0.0434" diaginertia="2.53693e-05 2.22687e-05 4.9021e-06"/>
      <joint name="right_hand_ring_0_joint" pos="0 0 0" axis="-1 0 0" range="-0.261799 0.261799" actuatorfrcrange="-0.2 0.2" damping="0.1" frictionloss="0.03"/>
      <geom type="mesh" mesh="right_hand_finger_0_link"/>
      <geom type="mesh" contype="0" conaffinity="0" group="1" density="0" rgba="0.2 0.2 0.2 1" mesh="right_hand_finger_0_link"/>
      <geom type="mesh" mesh="right_hand_finger_0_upper_link"/>
      <geom type="mesh" contype="0" conaffinity="0" group="1" density="0" rgba="0.2 0.2 0.2 1" mesh="right_hand_finger_0_upper_link"/>
      <body name="right_hand_ring_1_link" pos="-0.005 0 0.0215">
        <inertial pos="-0.00370794 0 0.0164775" quat="0.708493 0.0301359 0.0309677 0.704393" mass="0.035" diaginertia="2.17876e-05 2.09064e-05 1.87297e-06"/>
        <joint name="right_hand_ring_1_joint" pos="0 0 0" axis="0 1 0" range="0 1.5708" actuatorfrcrange="-0.2 0.2" damping="0.1" frictionloss="0.03"/>
        <geom type="mesh" mesh="right_hand_finger_1_link"/>
        <geom type="mesh" contype="0" conaffinity="0" group="1" density="0" rgba="0.2 0.2 0.2 1" mesh="right_hand_finger_1_link"/>
        <geom type="mesh" mesh="right_hand_finger_1_upper_link"/>
        <geom type="mesh" contype="0" conaffinity="0" group="1" density="0" rgba="0.2 0.2 0.2 1" mesh="right_hand_finger_1_upper_link"/>
        <geom type="mesh" mesh="right_hand_finger_1_front_link"/>
        <geom type="mesh" contype="0" conaffinity="0" group="1" density="0" rgba="0.2 0.2 0.2 1" mesh="right_hand_finger_1_front_link"/>
        <geom type="mesh" mesh="right_hand_finger_1_back_link"/>
        <geom type="mesh" contype="0" conaffinity="0" group="1" density="0" rgba="0.2 0.2 0.2 1" mesh="right_hand_finger_1_back_link"/>
        <body name="right_hand_ring_2_link" pos="-0.007 0 0.0475">
          <inertial pos="-0.0024886 0 0.00840977" quat="0.989776 0 -0.142633 0" mass="0.0043" diaginertia="7.24293e-07 6.35014e-07 1.49941e-07"/>
          <joint name="right_hand_ring_2_joint" pos="0 0 0" axis="0 1 0" range="0 1.5708" actuatorfrcrange="-0.2 0.2" damping="0.1" frictionloss="0.03"/>
          <geom type="mesh" mesh="right_hand_finger_2_link"/>
          <geom type="mesh" contype="0" conaffinity="0" group="1" density="0" rgba="0.2 0.2 0.2 1" mesh="right_hand_finger_2_link"/>
          <geom type="mesh" mesh="right_hand_finger_2_front_link"/>
          <geom type="mesh" contype="0" conaffinity="0" group="1" density="0" rgba="0.2 0.2 0.2 1" mesh="right_hand_finger_2_front_link"/>
          <geom type="mesh" mesh="right_hand_finger_2_back_link"/>
          <geom type="mesh" contype="0" conaffinity="0" group="1" density="0" rgba="0.2 0.2 0.2 1" mesh="right_hand_finger_2_back_link"/>
          <body name="right_hand_ring_3_link" pos="0.006217 0 0.026035">
            <inertial pos="-0.00237432 0 0.00990405" quat="0.996547 0.000445186 0.0829215 0.00419741" mass="0.0037" diaginertia="6.00078e-07 5.8879e-07 8.10134e-08"/>
            <joint name="right_hand_ring_3_joint" pos="0 0 0" axis="0 1 0" range="0 1.5708" actuatorfrcrange="-0.2 0.2" damping="0.1" frictionloss="0.03"/>
            <geom type="mesh" mesh="right_hand_finger_3_link"/>
            <geom type="mesh" contype="0" conaffinity="0" group="1" density="0" rgba="0.2 0.2 0.2 1" mesh="right_hand_finger_3_link"/>
            <geom type="mesh" mesh="right_hand_finger_3_front_link"/>
            <geom type="mesh" contype="0" conaffinity="0" group="1" density="0" rgba="0.2 0.2 0.2 1" mesh="right_hand_finger_3_front_link"/>
            <geom type="mesh" mesh="right_hand_finger_3_back_link"/>
            <geom type="mesh" contype="0" conaffinity="0" group="1" density="0" rgba="0.2 0.2 0.2 1" mesh="right_hand_finger_3_back_link"/>
          </body>
        </body>
      </body>
    </body>
    <body name="right_hand_little_0_link" pos="0.01475 -0.038 0.063">
      <inertial pos="-0.00990142 0 0.0170844" quat="0.699822 0.111023 0.111955 0.696699" mass="0.0381" diaginertia="2.67608e-05 2.4215e-05 3.64853e-06"/>
      <joint name="right_hand_little_0_joint" pos="0 0 0" axis="-1 0 0" range="-0.261799 0.261799" actuatorfrcrange="-0.2 0.2" damping="0.1" frictionloss="0.03"/>
      <geom type="mesh" mesh="right_hand_little_0_link"/>
      <geom type="mesh" contype="0" conaffinity="0" group="1" density="0" rgba="0.2 0.2 0.2 1" mesh="right_hand_little_0_link"/>
      <geom type="mesh" mesh="right_hand_little_0_upper_link"/>
      <geom type="mesh" contype="0" conaffinity="0" group="1" density="0" rgba="0.2 0.2 0.2 1" mesh="right_hand_little_0_upper_link"/>
      <geom type="mesh" mesh="right_hand_little_0_front_link"/>
      <geom type="mesh" contype="0" conaffinity="0" group="1" density="0" rgba="0.2 0.2 0.2 1" mesh="right_hand_little_0_front_link"/>
      <geom type="mesh" mesh="right_hand_little_0_back_link"/>
      <geom type="mesh" contype="0" conaffinity="0" group="1" density="0" rgba="0.2 0.2 0.2 1" mesh="right_hand_little_0_back_link"/>
      <body name="right_hand_little_1_link" pos="-0.0145 0 0.04825">
        <inertial pos="0.00351647 0 0.0161027" quat="0.995842 0 -0.0910921 0" mass="0.0051" diaginertia="2.61142e-06 2.5314e-06 1.65485e-07"/>
        <joint name="right_hand_little_1_joint" pos="0 0 0" axis="0 1 0" range="0 1.5708" actuatorfrcrange="-0.2 0.2" damping="0.1" frictionloss="0.03"/>
        <geom type="mesh" mesh="right_hand_little_1_link"/>
        <geom type="mesh" contype="0" conaffinity="0" group="1" density="0" rgba="0.2 0.2 0.2 1" mesh="right_hand_little_1_link"/>
        <geom type="mesh" mesh="right_hand_little_1_front_link"/>
        <geom type="mesh" contype="0" conaffinity="0" group="1" density="0" rgba="0.2 0.2 0.2 1" mesh="right_hand_little_1_front_link"/>
        <geom type="mesh" mesh="right_hand_little_1_back_link"/>
        <geom type="mesh" contype="0" conaffinity="0" group="1" density="0" rgba="0.2 0.2 0.2 1" mesh="right_hand_little_1_back_link"/>
        <body name="right_hand_little_2_link" pos="0.006217 0 0.039035">
          <inertial pos="-0.00237432 0 0.00990405" quat="0.996547 0.000445186 0.0829215 0.00419741" mass="0.0037" diaginertia="6.00078e-07 5.8879e-07 8.10134e-08"/>
          <joint name="right_hand_little_2_joint" pos="0 0 0" axis="0 1 0" range="0 1.5708" actuatorfrcrange="-0.2 0.2" damping="0.1" frictionloss="0.03"/>
          <geom type="mesh" mesh="right_hand_finger_3_link"/>
          <geom type="mesh" contype="0" conaffinity="0" group="1" density="0" rgba="0.2 0.2 0.2 1" mesh="right_hand_finger_3_link"/>
          <geom type="mesh" mesh="right_hand_finger_3_front_link"/>
          <geom type="mesh" contype="0" conaffinity="0" group="1" density="0" rgba="0.2 0.2 0.2 1" mesh="right_hand_finger_3_front_link"/>
          <geom type="mesh" mesh="right_hand_finger_3_back_link"/>
          <geom type="mesh" contype="0" conaffinity="0" group="1" density="0" rgba="0.2 0.2 0.2 1" mesh="right_hand_finger_3_back_link"/>
        </body>
      </body>
    </body>
  </worldbody>

  <default>
    <position kp="30" kv="0.7" forcerange="-1000 1000"/>
  </default>

  <actuator>
    <position name="right_hand_thumb_0_act"  joint="right_hand_thumb_0_joint"  ctrlrange="-0.7854 0.7854"/>
    <position name="right_hand_thumb_1_act"  joint="right_hand_thumb_1_joint"  ctrlrange="-0.7854 0.7854"/>
    <position name="right_hand_thumb_2_act"  joint="right_hand_thumb_2_joint"  ctrlrange="-1.0472 1.0472"/>
    <position name="right_hand_thumb_3_act"  joint="right_hand_thumb_3_joint"  ctrlrange="0 1.5708"/>
    <position name="right_hand_index_0_act"  joint="right_hand_index_0_joint"  ctrlrange="-0.261799 0.261799"/>
    <position name="right_hand_index_1_act"  joint="right_hand_index_1_joint"  ctrlrange="0 1.5708"/>
    <position name="right_hand_index_2_act"  joint="right_hand_index_2_joint"  ctrlrange="0 1.5708"/>
    <position name="right_hand_middle_0_act" joint="right_hand_middle_0_joint" ctrlrange="-0.261799 0.261799"/>
    <position name="right_hand_middle_1_act" joint="right_hand_middle_1_joint" ctrlrange="0 1.5708"/>
    <position name="right_hand_middle_2_act" joint="right_hand_middle_2_joint" ctrlrange="0 1.5708"/>
    <position name="right_hand_ring_0_act"   joint="right_hand_ring_0_joint"   ctrlrange="-0.261799 0.261799"/>
    <position name="right_hand_ring_1_act"   joint="right_hand_ring_1_joint"   ctrlrange="0 1.5708"/>
    <position name="right_hand_ring_2_act"   joint="right_hand_ring_2_joint"   ctrlrange="0 1.5708"/>
    <position name="right_hand_little_0_act" joint="right_hand_little_0_joint" ctrlrange="-0.261799 0.261799"/>
    <position name="right_hand_little_1_act" joint="right_hand_little_1_joint" ctrlrange="0 1.5708"/>
  </actuator>

  <!-- Kinematic 1:1 coupling (rigid linkage). -->
  <!-- solref="0.0005 1": 0.5ms time const (default 20ms) - near-instant tracking -->
  <!-- solimp="0.999 0.9999 1e-5": stiff constraint - virtually no slack -->
  <equality>
    <joint joint1="right_hand_index_3_joint"  joint2="right_hand_index_2_joint"  polycoef="0 1 0 0 0" solref="0.0005 1" solimp="0.999 0.9999 1e-5"/>
    <joint joint1="right_hand_middle_3_joint" joint2="right_hand_middle_2_joint" polycoef="0 1 0 0 0" solref="0.0005 1" solimp="0.999 0.9999 1e-5"/>
    <joint joint1="right_hand_ring_3_joint"   joint2="right_hand_ring_2_joint"   polycoef="0 1 0 0 0" solref="0.0005 1" solimp="0.999 0.9999 1e-5"/>
    <joint joint1="right_hand_thumb_4_joint"  joint2="right_hand_thumb_3_joint"  polycoef="0 1 0 0 0" solref="0.0005 1" solimp="0.999 0.9999 1e-5"/>
    <joint joint1="right_hand_little_2_joint" joint2="right_hand_little_1_joint" polycoef="0 1 0 0 0" solref="0.0005 1" solimp="0.999 0.9999 1e-5"/>
  </equality>
</mujoco>
